I ran on:
rice-a250
Traceback (most recent call last):
  File "/home/zhu442/pythonfolder/python3.6/lib/python3.6/urllib/request.py", line 1318, in do_open
    encode_chunked=req.has_header('Transfer-encoding'))
  File "/home/zhu442/pythonfolder/python3.6/lib/python3.6/http/client.py", line 1239, in request
    self._send_request(method, url, body, headers, encode_chunked)
  File "/home/zhu442/pythonfolder/python3.6/lib/python3.6/http/client.py", line 1285, in _send_request
    self.endheaders(body, encode_chunked=encode_chunked)
  File "/home/zhu442/pythonfolder/python3.6/lib/python3.6/http/client.py", line 1234, in endheaders
    self._send_output(message_body, encode_chunked=encode_chunked)
  File "/home/zhu442/pythonfolder/python3.6/lib/python3.6/http/client.py", line 1026, in _send_output
    self.send(msg)
  File "/home/zhu442/pythonfolder/python3.6/lib/python3.6/http/client.py", line 964, in send
    self.connect()
  File "/home/zhu442/pythonfolder/python3.6/lib/python3.6/http/client.py", line 1392, in connect
    super().connect()
  File "/home/zhu442/pythonfolder/python3.6/lib/python3.6/http/client.py", line 936, in connect
    (self.host,self.port), self.timeout, self.source_address)
  File "/home/zhu442/pythonfolder/python3.6/lib/python3.6/socket.py", line 724, in create_connection
    raise err
  File "/home/zhu442/pythonfolder/python3.6/lib/python3.6/socket.py", line 713, in create_connection
    sock.connect(sa)
TimeoutError: [Errno 110] Connection timed out

During handling of the above exception, another exception occurred:

Traceback (most recent call last):
  File "save-transfer.py", line 280, in Minnesota
    response = urllib.request.urlretrieve(Min_url, filepath)
  File "/home/zhu442/pythonfolder/python3.6/lib/python3.6/urllib/request.py", line 248, in urlretrieve
    with contextlib.closing(urlopen(url, data)) as fp:
  File "/home/zhu442/pythonfolder/python3.6/lib/python3.6/urllib/request.py", line 223, in urlopen
    return opener.open(url, data, timeout)
  File "/home/zhu442/pythonfolder/python3.6/lib/python3.6/urllib/request.py", line 526, in open
    response = self._open(req, data)
  File "/home/zhu442/pythonfolder/python3.6/lib/python3.6/urllib/request.py", line 544, in _open
    '_open', req)
  File "/home/zhu442/pythonfolder/python3.6/lib/python3.6/urllib/request.py", line 504, in _call_chain
    result = func(*args)
  File "/home/zhu442/pythonfolder/python3.6/lib/python3.6/urllib/request.py", line 1361, in https_open
    context=self._context, check_hostname=self._check_hostname)
  File "/home/zhu442/pythonfolder/python3.6/lib/python3.6/urllib/request.py", line 1320, in do_open
    raise URLError(err)
urllib.error.URLError: <urlopen error [Errno 110] Connection timed out>

During handling of the above exception, another exception occurred:

Traceback (most recent call last):
  File "save-transfer.py", line 353, in <module>
    main()
  File "save-transfer.py", line 347, in main
    Minnesota()
  File "save-transfer.py", line 281, in Minnesota
    except (URLError,TimeoutError,OSError) as e:
NameError: name 'URLError' is not defined
